Workbook

Sheet 假设与WACC
A1: 贵州茅台（600519.SH）DCF 模型 — 假设与 WACC
A2: 估值日期 2026-08-31 ｜ Rf=中债10年期国债收益率（用户指定）｜ 黄色单元格=可修改输入
A4: 一、市场与股本数据
A5: 现价（元，2026-08-31收盘） | B5: 1299.52 | E5: 腾讯行情
A6: 总股本（亿股，2026H1末） | B6: 12.5 | E6: 2026中报；回购注销后由12.5227亿下降
A7: 总市值（亿元） | B7: =B5*B6 | E7: 计算：现价×股本
A8: PE(TTM) | B8: =B7/814.34 | E8: TTM归母净利814.34亿；与行情19.95核对一致
A9: PB(MRQ) | B9: 6.47 | E9: 腾讯行情
A11: 二、WACC 计算（CAPM）
A12: 无风险利率 Rf（中债10Y，%） | B12: 1.6883 | E12: akshare bond_zh_us_rate，2026-08-31
A13: β 原始值（vs 上证指数） | B13: 0.665 | E13: 新浪日线2年日收益回归（3年0.667/2年0.665/1年0.115不可靠）
A14: β Blume调整 = 2/3×β+1/3 | B14: =2/3*B13+1/3 | E14: 向1回归的标准调整
A15: 有息负债 D（亿元） | B15: 0 | E15: 茅台无有息负债（负债均为经营性），故 WACC 即 Ke
A16: WACC（%） | B16: =B14*B17+$B$12 | C16: =B14*C17+$B$12 | D16: =B14*D17+$B$12 | E16: 公式：Rf + β×ERP（D为0）
A17: ERP（股权风险溢价，%） | B17: 9 | C17: 7.5 | D17: 6.5 | E17: A股ERP取6-8%区间：悲观9.0/中性7.5/乐观6.5
A18: 三、三情景 DCF 假设
A19: 参数 | B19: 悲观 | C19: 中性 | D19: 乐观 | E19: 备注
A20: 2026E 归母净利（亿元） | B20: 790 | C20: 820 | D20: 850 | E20: H1实际445.17亿(-1.95%)+H2推算
A21: FCF 转化率（FCF/净利） | B21: 0.98 | C21: 0.98 | D21: 0.98 | E21: 净利-净再投资（CapEx约30亿-D&A约18亿-ΔWC）
A22: FCF 基期 2026E（亿元） | B22: =B20*B21 | C22: =C20*C21 | D22: =D20*D21 | E22: 计算：净利×转化率
A23: 显性期增速 g5（2027-31E，%） | B23: 1 | C23: 5 | D23: 8 | E23: 悲观=行业停滞；中性=温和恢复；乐观=量价周期回归
A24: 永续增长率 g（%） | B24: 1.5 | C24: 3 | D24: 3.5 | E24: 上限锚定长期中国名义GDP

Sheet DCF模型
A1: 三情景 DCF — 显性期5年（2027E-2031E）+ 永续
A3: 情景汇总
A4: 指标 | B4: 悲观 | C4: 中性 | D4: 乐观 | E4: 现价对照
A5: WACC（%） | B5: =假设与WACC!B16 | C5: =假设与WACC!C16 | D5: =假设与WACC!D16
A6: 股权价值（亿元） | B6: =B22 | C6: =B37 | D6: =B52 | E6: =假设与WACC!B7
A7: 每股价值（元） | B7: =B23 | C7: =B38 | D7: =B53 | E7: =假设与WACC!B5
A8: 较现价空间 | B8: =B24 | C8: =B39 | D8: =B54
A9: 永续TV占比 | B9: =B25 | C9: =B40 | D9: =B55
A12: —— 悲观情景 ——
A13: 项目 | B13: 2027E | C13: 2028E | D13: 2029E | E13: 2030E | F13: 2031E | G13: 永续TV
A14: FCF（亿元） | B14: =假设与WACC!B22 | C14: =B14*(1+假设与WACC!B23/100) | D14: =C14*(1+假设与WACC!B23/100) | E14: =D14*(1+假设与WACC!B23/100) | F14: =E14*(1+假设与WACC!B23/100) | G14: =F14*(1+假设与WACC!B24/100)/((假设与WACC!B16-假设与WACC!B24)/100)
A15: 折现因子 | B15: =1/(1+假设与WACC!B16/100)^1 | C15: =1/(1+假设与WACC!B16/100)^2 | D15: =1/(1+假设与WACC!B16/100)^3 | E15: =1/(1+假设与WACC!B16/100)^4 | F15: =1/(1+假设与WACC!B16/100)^5 | G15: =F15
A16: PV(FCF) | B16: =B14*B15 | C16: =C14*C15 | D16: =D14*D15 | E16: =E14*E15 | F16: =F14*F15 | G16: =G14*G15
A20: 显性期PV合计（亿元） | B20: =SUM(B16:F16)
A21: 永续TV现值（亿元） | B21: =G16
A22: 股权价值（亿元） | B22: =B20+B21
A23: 每股价值（元） | B23: =B22/假设与WACC!$B$6
A24: 较现价空间 | B24: =B23/假设与WACC!$B$5-1
A25: 永续TV占比 | B25: =B21/B22
A27: —— 中性情景 ——
A28: 项目 | B28: 2027E | C28: 2028E | D28: 2029E | E28: 2030E | F28: 2031E | G28: 永续TV
A29: FCF（亿元） | B29: =假设与WACC!C22 | C29: =B29*(1+假设与WACC!C23/100) | D29: =C29*(1+假设与WACC!C23/100) | E29: =D29*(1+假设与WACC!C23/100) | F29: =E29*(1+假设与WACC!C23/100) | G29: =F29*(1+假设与WACC!C24/100)/((假设与WACC!C16-假设与WACC!C24)/100)
A30: 折现因子 | B30: =1/(1+假设与WACC!C16/100)^1 | C30: =1/(1+假设与WACC!C16/100)^2 | D30: =1/(1+假设与WACC!C16/100)^3 | E30: =1/(1+假设与WACC!C16/100)^4 | F30: =1/(1+假设与WACC!C16/100)^5 | G30: =F30
A31: PV(FCF) | B31: =B29*B30 | C31: =C29*C30 | D31: =D29*D30 | E31: =E29*E30 | F31: =F29*F30 | G31: =G29*G30
A35: 显性期PV合计（亿元） | B35: =SUM(B31:F31)
A36: 永续TV现值（亿元） | B36: =G31
A37: 股权价值（亿元） | B37: =B35+B36
A38: 每股价值（元） | B38: =B37/假设与WACC!$B$6
A39: 较现价空间 | B39: =B38/假设与WACC!$B$5-1
A40: 永续TV占比 | B40: =B36/B37
A42: —— 乐观情景 ——
A43: 项目 | B43: 2027E | C43: 2028E | D43: 2029E | E43: 2030E | F43: 2031E | G43: 永续TV
A44: FCF（亿元） | B44: =假设与WACC!D22 | C44: =B44*(1+假设与WACC!D23/100) | D44: =C44*(1+假设与WACC!D23/100) | E44: =D44*(1+假设与WACC!D23/100) | F44: =E44*(1+假设与WACC!D23/100) | G44: =F44*(1+假设与WACC!D24/100)/((假设与WACC!D16-假设与WACC!D24)/100)
A45: 折现因子 | B45: =1/(1+假设与WACC!D16/100)^1 | C45: =1/(1+假设与WACC!D16/100)^2 | D45: =1/(1+假设与WACC!D16/100)^3 | E45: =1/(1+假设与WACC!D16/100)^4 | F45: =1/(1+假设与WACC!D16/100)^5 | G45: =F45
A46: PV(FCF) | B46: =B44*B45 | C46: =C44*C45 | D46: =D44*D45 | E46: =E44*E45 | F46: =F44*F45 | G46: =G44*G45
A50: 显性期PV合计（亿元） | B50: =SUM(B46:F46)
A51: 永续TV现值（亿元） | B51: =G46
A52: 股权价值（亿元） | B52: =B50+B51
A53: 每股价值（元） | B53: =B52/假设与WACC!$B$6
A54: 较现价空间 | B54: =B53/假设与WACC!$B$5-1
...

Sheet 敏感性
A1: 敏感性分析：每股价值（元）= f(WACC, 永续g)
A2: 固定中性情景FCF路径（第3行辅助计算，联动"假设与WACC"表），扫描WACC×永续g
A3: 中性FCF路径（亿元） | B3: =假设与WACC!$C$22*(1+假设与WACC!$C$23/100)^1 | C3: =假设与WACC!$C$22*(1+假设与WACC!$C$23/100)^2 | D3: =假设与WACC!$C$22*(1+假设与WACC!$C$23/100)^3 | E3: =假设与WACC!$C$22*(1+假设与WACC!$C$23/100)^4 | F3: =假设与WACC!$C$22*(1+假设与WACC!$C$23/100)^5
A4: WACC\永续g | B4: 0.015 | C4: 0.02 | D4: 0.025 | E4: 0.03 | F4: 0.035
A5: 0.065 | B5: =IF($A5<=B$4+0.0001,"n/a",(B$3/(1+$A5)^1+C$3/(1+$A5)^2+D$3/(1+$A5)^3+E$3/(1+$A5)^4+F$3/(1+$A5)^5+F$3*(1+B$4)/($A5-B$4)/(1+$A5)^5)/假设与WACC!$B$6) | C5: =IF($A5<=C$4+0.0001,"n/a",(B$3/(1+$A5)^1+C$3/(1+$A5)^2+D$3/(1+$A5)^3+E$3/(1+$A5)^4+F$3/(1+$A5)^5+F$3*(1+C$4)/($A5-C$4)/(1+$A5)^5)/假设与WACC!$B$6) | D5: =IF($A5<=D$4+0.0001,"n/a",(B$3/(1+$A5)^1+C$3/(1+$A5)^2+D$3/(1+$A5)^3+E$3/(1+$A5)^4+F$3/(1+$A5)^5+F$3*(1+D$4)/($A5-D$4)/(1+$A5)^5)/假设与WACC!$B$6) | E5: =IF($A5<=E$4+0.0001,"n/a",(B$3/(1+$A5)^1+C$3/(1+$A5)^2+D$3/(1+$A5)^3+E$3/(1+$A5)^4+F$3/(1+$A5)^5+F$3*(1+E$4)/($A5-E$4)/(1+$A5)^5)/假设与WACC!$B$6) | F5: =IF($A5<=F$4+0.0001,"n/a",(B$3/(1+$A5)^1+C$3/(1+$A5)^2+D$3/(1+$A5)^3+E$3/(1+$A5)^4+F$3/(1+$A5)^5+F$3*(1+F$4)/($A5-F$4)/(1+$A5)^5)/假设与WACC!$B$6)
A6: 0.07 | B6: =IF($A6<=B$4+0.0001,"n/a",(B$3/(1+$A6)^1+C$3/(1+$A6)^2+D$3/(1+$A6)^3+E$3/(1+$A6)^4+F$3/(1+$A6)^5+F$3*(1+B$4)/($A6-B$4)/(1+$A6)^5)/假设与WACC!$B$6) | C6: =IF($A6<=C$4+0.0001,"n/a",(B$3/(1+$A6)^1+C$3/(1+$A6)^2+D$3/(1+$A6)^3+E$3/(1+$A6)^4+F$3/(1+$A6)^5+F$3*(1+C$4)/($A6-C$4)/(1+$A6)^5)/假设与WACC!$B$6) | D6: =IF($A6<=D$4+0.0001,"n/a",(B$3/(1+$A6)^1+C$3/(1+$A6)^2+D$3/(1+$A6)^3+E$3/(1+$A6)^4+F$3/(1+$A6)^5+F$3*(1+D$4)/($A6-D$4)/(1+$A6)^5)/假设与WACC!$B$6) | E6: =IF($A6<=E$4+0.0001,"n/a",(B$3/(1+$A6)^1+C$3/(1+$A6)^2+D$3/(1+$A6)^3+E$3/(1+$A6)^4+F$3/(1+$A6)^5+F$3*(1+E$4)/($A6-E$4)/(1+$A6)^5)/假设与WACC!$B$6) | F6: =IF($A6<=F$4+0.0001,"n/a",(B$3/(1+$A6)^1+C$3/(1+$A6)^2+D$3/(1+$A6)^3+E$3/(1+$A6)^4+F$3/(1+$A6)^5+F$3*(1+F$4)/($A6-F$4)/(1+$A6)^5)/假设与WACC!$B$6)
A7: 0.075 | B7: =IF($A7<=B$4+0.0001,"n/a",(B$3/(1+$A7)^1+C$3/(1+$A7)^2+D$3/(1+$A7)^3+E$3/(1+$A7)^4+F$3/(1+$A7)^5+F$3*(1+B$4)/($A7-B$4)/(1+$A7)^5)/假设与WACC!$B$6) | C7: =IF($A7<=C$4+0.0001,"n/a",(B$3/(1+$A7)^1+C$3/(1+$A7)^2+D$3/(1+$A7)^3+E$3/(1+$A7)^4+F$3/(1+$A7)^5+F$3*(1+C$4)/($A7-C$4)/(1+$A7)^5)/假设与WACC!$B$6) | D7: =IF($A7<=D$4+0.0001,"n/a",(B$3/(1+$A7)^1+C$3/(1+$A7)^2+D$3/(1+$A7)^3+E$3/(1+$A7)^4+F$3/(1+$A7)^5+F$3*(1+D$4)/($A7-D$4)/(1+$A7)^5)/假设与WACC!$B$6) | E7: =IF($A7<=E$4+0.0001,"n/a",(B$3/(1+$A7)^1+C$3/(1+$A7)^2+D$3/(1+$A7)^3+E$3/(1+$A7)^4+F$3/(1+$A7)^5+F$3*(1+E$4)/($A7-E$4)/(1+$A7)^5)/假设与WACC!$B$6) | F7: =IF($A7<=F$4+0.0001,"n/a",(B$3/(1+$A7)^1+C$3/(1+$A7)^2+D$3/(1+$A7)^3+E$3/(1+$A7)^4+F$3/(1+$A7)^5+F$3*(1+F$4)/($A7-F$4)/(1+$A7)^5)/假设与WACC!$B$6)
A8: 0.08 | B8: =IF($A8<=B$4+0.0001,"n/a",(B$3/(1+$A8)^1+C$3/(1+$A8)^2+D$3/(1+$A8)^3+E$3/(1+$A8)^4+F$3/(1+$A8)^5+F$3*(1+B$4)/($A8-B$4)/(1+$A8)^5)/假设与WACC!$B$6) | C8: =IF($A8<=C$4+0.0001,"n/a",(B$3/(1+$A8)^1+C$3/(1+$A8)^2+D$3/(1+$A8)^3+E$3/(1+$A8)^4+F$3/(1+$A8)^5+F$3*(1+C$4)/($A8-C$4)/(1+$A8)^5)/假设与WACC!$B$6) | D8: =IF($A8<=D$4+0.0001,"n/a",(B$3/(1+$A8)^1+C$3/(1+$A8)^2+D$3/(1+$A8)^3+E$3/(1+$A8)^4+F$3/(1+$A8)^5+F$3*(1+D$4)/($A8-D$4)/(1+$A8)^5)/假设与WACC!$B$6) | E8: =IF($A8<=E$4+0.0001,"n/a",(B$3/(1+$A8)^1+C$3/(1+$A8)^2+D$3/(1+$A8)^3+E$3/(1+$A8)^4+F$3/(1+$A8)^5+F$3*(1+E$4)/($A8-E$4)/(1+$A8)^5)/假设与WACC!$B$6) | F8: =IF($A8<=F$4+0.0001,"n/a",(B$3/(1+$A8)^1+C$3/(1+$A8)^2+D$3/(1+$A8)^3+E$3/(1+$A8)^4+F$3/(1+$A8)^5+F$3*(1+F$4)/($A8-F$4)/(1+$A8)^5)/假设与WACC!$B$6)
A9: 0.085 | B9: =IF($A9<=B$4+0.0001,"n/a",(B$3/(1+$A9)^1+C$3/(1+$A9)^2+D$3/(1+$A9)^3+E$3/(1+$A9)^4+F$3/(1+$A9)^5+F$3*(1+B$4)/($A9-B$4)/(1+$A9)^5)/假设与WACC!$B$6) | C9: =IF($A9<=C$4+0.0001,"n/a",(B$3/(1+$A9)^1+C$3/(1+$A9)^2+D$3/(1+$A9)^3+E$3/(1+$A9)^4+F$3/(1+$A9)^5+F$3*(1+C$4)/($A9-C$4)/(1+$A9)^5)/假设与WACC!$B$6) | D9: =IF($A9<=D$4+0.0001,"n/a",(B$3/(1+$A9)^1+C$3/(1+$A9)^2+D$3/(1+$A9)^3+E$3/(1+$A9)^4+F$3/(1+$A9)^5+F$3*(1+D$4)/($A9-D$4)/(1+$A9)^5)/假设与WACC!$B$6) | E9: =IF($A9<=E$4+0.0001,"n/a",(B$3/(1+$A9)^1+C$3/(1+$A9)^2+D$3/(1+$A9)^3+E$3/(1+$A9)^4+F$3/(1+$A9)^5+F$3*(1+E$4)/($A9-E$4)/(1+$A9)^5)/假设与WACC!$B$6) | F9: =IF($A9<=F$4+0.0001,"n/a",(B$3/(1+$A9)^1+C$3/(1+$A9)^2+D$3/(1+$A9)^3+E$3/(1+$A9)^4+F$3/(1+$A9)^5+F$3*(1+F$4)/($A9-F$4)/(1+$A9)^5)/假设与WACC!$B$6)
A10: 0.09 | B10: =IF($A10<=B$4+0.0001,"n/a",(B$3/(1+$A10)^1+C$3/(1+$A10)^2+D$3/(1+$A10)^3+E$3/(1+$A10)^4+F$3/(1+$A10)^5+F$3*(1+B$4)/($A10-B$4)/(1+$A10)^5)/假设与WACC!$B$6) | C10: =IF($A10<=C$4+0.0001,"n/a",(B$3/(1+$A10)^1+C$3/(1+$A10)^2+D$3/(1+$A10)^3+E$3/(1+$A10)^4+F$3/(1+$A10)^5+F$3*(1+C$4)/($A10-C$4)/(1+$A10)^5)/假设与WACC!$B$6) | D10: =IF($A10<=D$4+0.0001,"n/a",(B$3/(1+$A10)^1+C$3/(1+$A10)^2+D$3/(1+$A10)^3+E$3/(1+$A10)^4+F$3/(1+$A10)^5+F$3*(1+D$4)/($A10-D$4)/(1+$A10)^5)/假设与WACC!$B$6) | E10: =IF($A10<=E$4+0.0001,"n/a",(B$3/(1+$A10)^1+C$3/(1+$A10)^2+D$3/(1+$A10)^3+E$3/(1+$A10)^4+F$3/(1+$A10)^5+F$3*(1+E$4)/($A10-E$4)/(1+$A10)^5)/假设与WACC!$B$6) | F10: =IF($A10<=F$4+0.0001,"n/a",(B$3/(1+$A10)^1+C$3/(1+$A10)^2+D$3/(1+$A10)^3+E$3/(1+$A10)^4+F$3/(1+$A10)^5+F$3*(1+F$4)/($A10-F$4)/(1+$A10)^5)/假设与WACC!$B$6)
A13: 反向 DCF 审计（现价 1299.52 元 / 市值 16,245 亿）
A14: 市场价隐含前5年FCF增速 | B14: ≈ 0.28%/年 | D14: 在中性 WACC 7.51%、永续 g 3.0% 下
A15: 市场价隐含 WACC | B15: ≈ 8.57% | D15: 在5年增速5%、永续 g 3.0% 下；等价 ERP ≈ 8.9%
A16: 解读 | B16: 停滞 或 高折现率，二选一 | D16: 两种解释均指向：中性假设下现价存在安全边际

Sheet 数据底稿
A1: 数据底稿与来源（采集日 2026-08-31）
A3: 科目（亿元） | B3: 2021A | C3: 2022A | D3: 2023A | E3: 2024A | F3: 2025A
A4: 营业收入 | B4: 1061.9 | C4: 1241 | D4: 1476.94 | E4: 1708.99 | F4: 1688.38
A5: 归母净利润 | B5: 524.6 | C5: 627.17 | D5: 747.34 | E5: 862.28 | F5: 823.2
A6: 营收增速 | C6: 0.169 | D6: 0.19 | E6: 0.157 | F6: -0.012
A7: 净利增速 | C7: 0.196 | D7: 0.192 | E7: 0.154 | F7: -0.045
A8: 经营现金流净额 | D8: 665.93 | E8: 924.64 | F8: 615.22
A9: CapEx | D9: 26.2 | E9: 46.79 | F9: 31.28
A10: OCF-CapEx（财务公司扭曲） | D10: 639.73 | E10: 877.85 | F10: 583.94
A11: 分红支付 | D11: 587.55 | E11: 709.51 | F11: 672.42
A14: 2026H1 实际（中报2026-08-15披露）
A15: 营业收入 | B15: 907.03 | D15: +1.48% vs 2025H1 893.89亿
A16: 归母净利润 | B16: 445.17 | D16: -1.95% vs 2025H1 454.03亿
A17: 经营现金流净额 | B17: 706.91 | D17: 受财务公司存款波动影响（2025H1仅131.19亿），不可直接年化
A18: CapEx | B18: 8.32 | D18: 全年预计20-30亿
A19: 分红支付 | B19: 350.44 | D19: 2025年度末期股利28.0242元/股
A20: 2025年度DPS合计（元） | B20: 51.98 | D20: 中期23.957+年度28.0242；现价股息率4.00%，分红率79.1%
A23: Beta 回归与 WACC 输入
A24: β（近3年，vs 上证指数） | B24: 0.667
A25: β（近2年，采用） | B25: 0.665
A26: β（近1年） | B26: 0.115
A27: Blume调整β（模型采用） | B27: 0.777
A28: Rf 中债10Y（2026-08-31） | B28: 1.6883%
A29: 茅台年化波动率（2年） | B29: 24.4%
A30: 与上证相关系数（2年） | B30: 0.471
A31: 有效所得税率（2025） | B31: 25.7%
A33: 数据来源：AkShare（新浪财经财报接口/中债国债收益率/新浪日线）、腾讯行情（2026-08-31收盘）、贵州茅台2026年中报（2026-08-15披露）、业绩说明会（2026-08-21，陈华/王莉发言）、知识库《茅台估值假设》
