Workbook

Sheet 假设与情景
A1: 贵州茅台（600519.SH）三表联动模型 — 假设与情景
A2: 单位: 人民币亿元（另注明者除外）｜ 黄底蓝字=可修改输入 ｜ 历史比率由2025A实际值锚定
A4: 一、市场与股本
A5: 现价（元, 2026-08-31收盘） | B5: 1299.52
A6: 总股本（亿股, 2026H1末） | B6: 12.52
A7: 2025A 全年DPS（元） | B7: 51.98
A9: 二、2025A 实际比率（锚定值, 仅参考）
A10: 毛利率 | B10: 0.91
A11: 税金及附加/营收 | B11: 0.16
A12: 销售费用率 | B12: 0.04
A13: 管理费用率（不含研发） | B13: 0.05
A14: 研发费用率 | B14: 0
A15: 有效税率 | B15: 0.26
A16: 少数股东损益/净利润 | B16: 0.04
A17: 存货/营收 | B17: 0.36
A18: 合同负债/营收 | B18: 0.05
A19: 应收款项融资/营收 | B19: 0.03
A20: 其他经营性负债/营收 | B20: 0.14
A22: 三、情景假设（2026E-2030E 驱动参数）
A23: 参数 | B23: 悲观 | C23: 中性 | D23: 乐观 | E23: 备注
A24: 营收增速 2026E | B24: -0.02 | C24: 0.02 | D24: 0.04 | E24: 2026H1实际+1.5%；悲观=行业调整深化
A25: 营收增速 2027E | B25: 0 | C25: 0.05 | D25: 0.08
A26: 营收增速 2028E | B26: 0.01 | C26: 0.05 | D26: 0.08
A27: 营收增速 2029E | B27: 0.01 | C27: 0.04 | D27: 0.07
A28: 营收增速 2030E | B28: 0.01 | C28: 0.04 | D28: 0.06 | E28: 长期锚定高端白酒量价
A29: 毛利率 | B29: 0.912 | C29: 0.912 | D29: 0.912 | E29: 2025A实际91.2%，茅台酒成本结构极稳定
A30: 税金及附加/营收 | B30: 0.165 | C30: 0.162 | D30: 0.16 | E30: 2023-25年: 15.1%/15.8%/16.2%（消费税口径收紧）
A31: 销售费用率 | B31: 0.046 | C31: 0.04 | D31: 0.038 | E31: 2025A实际4.30%（渠道与市场投入加大）
A32: 管理费用率（不含研发） | B32: 0.051 | C32: 0.048 | D32: 0.047 | E32: 2025A实际4.93%
A33: 研发费用率 | B33: 0.0011 | C33: 0.0011 | D33: 0.0011
A34: 有效税率 | B34: 0.258 | C34: 0.257 | D34: 0.256 | E34: 2025A实际25.66%
A35: 少数股东损益/净利润 | B35: 0.036 | C35: 0.035 | D35: 0.034 | E35: 2025A实际3.50%（酱香系列酒等子公司）
A36: 分红率（占归母净利） | B36: 0.75 | C36: 0.78 | D36: 0.8 | E36: 2025A实际约79%；假设当年宣派当年支付
A37: 年回购额（亿） | B37: 0 | C37: 40 | D37: 50 | E37: 2025年支付其他筹资61.85亿（回购为主）
A38: CapEx（亿/年） | B38: 30 | C38: 40 | D38: 50 | E38: 2023-25年: 26.2/46.8/31.3；产能扩建周期
A39: 存货/营收 | B39: 0.37 | C39: 0.36 | D39: 0.355 | E39: 2025A实际36.4%（基酒储备持续积累）
A40: 合同负债/营收 | B40: 0.045 | C40: 0.047 | D40: 0.05 | E40: 2025A实际4.74%（经销商打款意愿）
A41: 应收款项融资/营收 | B41: 0.026 | C41: 0.026 | D41: 0.026 | E41: 银行承兑汇票
A42: 其他经营性负债/营收 | B42: 0.141 | C42: 0.141 | D42: 0.141 | E42: 应付+职工薪酬+税费+其他应付等
A43: 盈余公积提取率（占归母净利） | B43: 0.0475 | C43: 0.0475 | D43: 0.0475 | E43: 法定10%×母公司报表净利(约为归母47.5%)
...

Sheet 利润表
A1: 利润表（合并口径）
A2: 单位: 人民币亿元 ｜ 历史=蓝字输入, 预测=公式（黑字本表/绿字跨表）
B3: 历史实际（AkShare/年报） | E3: 悲观情景 | J3: 中性情景 | O3: 乐观情景
B4: 2023A | C4: 2024A | D4: 2025A | E4: 2026E | F4: 2027E | G4: 2028E | H4: 2029E | I4: 2030E | J4: 2026E | K4: 2027E | L4: 2028E | M4: 2029E | N4: 2030E | O4: 2026E | P4: 2027E | Q4: 2028E | R4: 2029E | S4: 2030E
A6: 营业收入（酒类及其他主营） | B6: 1476.94 | C6: 1708.99 | D6: 1688.38 | E6: =D6*(1+假设与情景!$B$24) | F6: =E6*(1+假设与情景!$B$25) | G6: =F6*(1+假设与情景!$B$26) | H6: =G6*(1+假设与情景!$B$27) | I6: =H6*(1+假设与情景!$B$28) | J6: =D6*(1+假设与情景!$C$24) | K6: =J6*(1+假设与情景!$C$25) | L6: =K6*(1+假设与情景!$C$26) | M6: =L6*(1+假设与情景!$C$27) | N6: =M6*(1+假设与情景!$C$28) | O6: =D6*(1+假设与情景!$D$24) | P6: =O6*(1+假设与情景!$D$25) | Q6: =P6*(1+假设与情景!$D$26) | R6: =Q6*(1+假设与情景!$D$27) | S6: =R6*(1+假设与情景!$D$28)
A7: 利息及其他收入（财务公司） | B7: 28.67 | C7: 32.45 | D7: 32.16 | E7: =假设与情景!$B$47 | F7: =假设与情景!$B$47 | G7: =假设与情景!$B$47 | H7: =假设与情景!$B$47 | I7: =假设与情景!$B$47 | J7: =假设与情景!$C$47 | K7: =假设与情景!$C$47 | L7: =假设与情景!$C$47 | M7: =假设与情景!$C$47 | N7: =假设与情景!$C$47 | O7: =假设与情景!$D$47 | P7: =假设与情景!$D$47 | Q7: =假设与情景!$D$47 | R7: =假设与情景!$D$47 | S7: =假设与情景!$D$47
A8: 营业总收入 | B8: =SUM(B6:B7) | C8: =SUM(C6:C7) | D8: =SUM(D6:D7) | E8: =SUM(E6:E7) | F8: =SUM(F6:F7) | G8: =SUM(G6:G7) | H8: =SUM(H6:H7) | I8: =SUM(I6:I7) | ... S8: =SUM(S6:S7)
A9: 营业成本 | B9: 118.67 | C9: 137.89 | D9: 148.92 | E9: =E6*(1-假设与情景!$B$29) | F9: =F6*(1-假设与情景!$B$29) | G9: =G6*(1-假设与情景!$B$29) | H9: =H6*(1-假设与情景!$B$29) | I9: =I6*(1-假设与情景!$B$29) | J9: =J6*(1-假设与情景!$C$29) | K9: =K6*(1-假设与情景!$C$29) | L9: =L6*(1-假设与情景!$C$29) | M9: =M6*(1-假设与情景!$C$29) | N9: =N6*(1-假设与情景!$C$29) | O9: =O6*(1-假设与情景!$D$29) | P9: =P6*(1-假设与情景!$D$29) | Q9: =Q6*(1-假设与情景!$D$29) | R9: =R6*(1-假设与情景!$D$29) | S9: =S6*(1-假设与情景!$D$29)
A10: 税金及附加 | B10: 222.34 | C10: 269.26 | D10: 273.54 | E10: =E6*假设与情景!$B$30 | F10: =F6*假设与情景!$B$30 | G10: =G6*假设与情景!$B$30 | H10: =H6*假设与情景!$B$30 | I10: =I6*假设与情景!$B$30 | J10: =J6*假设与情景!$C$30 | K10: =K6*假设与情景!$C$30 | L10: =L6*假设与情景!$C$30 | M10: =M6*假设与情景!$C$30 | N10: =N6*假设与情景!$C$30 | O10: =O6*假设与情景!$D$30 | P10: =P6*假设与情景!$D$30 | Q10: =Q6*假设与情景!$D$30 | R10: =R6*假设与情景!$D$30 | S10: =S6*假设与情景!$D$30
A11: 销售费用 | B11: 46.49 | C11: 56.39 | D11: 72.53 | E11: =E6*假设与情景!$B$31 | F11: =F6*假设与情景!$B$31 | G11: =G6*假设与情景!$B$31 | H11: =H6*假设与情景!$B$31 | I11: =I6*假设与情景!$B$31 | J11: =J6*假设与情景!$C$31 | K11: =K6*假设与情景!$C$31 | L11: =L6*假设与情景!$C$31 | M11: =M6*假设与情景!$C$31 | N11: =N6*假设与情景!$C$31 | O11: =O6*假设与情景!$D$31 | P11: =P6*假设与情景!$D$31 | Q11: =Q6*假设与情景!$D$31 | R11: =R6*假设与情景!$D$31 | S11: =S6*假设与情景!$D$31
A12: 管理费用 | B12: 97.29 | C12: 93.16 | D12: 83.2 | E12: =E6*假设与情景!$B$32 | F12: =F6*假设与情景!$B$32 | G12: =G6*假设与情景!$B$32 | H12: =H6*假设与情景!$B$32 | I12: =I6*假设与情景!$B$32 | J12: =J6*假设与情景!$C$32 | K12: =K6*假设与情景!$C$32 | L12: =L6*假设与情景!$C$32 | M12: =M6*假设与情景!$C$32 | N12: =N6*假设与情景!$C$32 | O12: =O6*假设与情景!$D$32 | P12: =P6*假设与情景!$D$32 | Q12: =Q6*假设与情景!$D$32 | R12: =R6*假设与情景!$D$32 | S12: =S6*假设与情景!$D$32
A13: 研发费用 | B13: 1.57 | C13: 2.18 | D13: 1.9 | E13: =E6*假设与情景!$B$33 | F13: =F6*假设与情景!$B$33 | G13: =G6*假设与情景!$B$33 | H13: =H6*假设与情景!$B$33 | I13: =I6*假设与情景!$B$33 | J13: =J6*假设与情景!$C$33 | K13: =K6*假设与情景!$C$33 | L13: =L6*假设与情景!$C$33 | M13: =M6*假设与情景!$C$33 | N13: =N6*假设与情景!$C$33 | O13: =O6*假设与情景!$D$33 | P13: =P6*假设与情景!$D$33 | Q13: =Q6*假设与情景!$D$33 | R13: =R6*假设与情景!$D$33 | S13: =S6*假设与情景!$D$33
A14: 财务费用（负=利息净收益） | B14: -17.9 | C14: -14.7 | D14: -8.15 | E14: =-假设与情景!$B$46*资产负债表!D6 | F14: =-假设与情景!$B$46*资产负债表!E6 | G14: =-假设与情景!$B$46*资产负债表!F6 | H14: =-假设与情景!$B$46*资产负债表!G6 | I14: =-假设与情景!$B$46*资产负债表!H6 | J14: =-假设与情景!$C$46*资产负债表!D6 | K14: =-假设与情景!$C$46*资产负债表!J6 | L14: =-假设与情景!$C$46*资产负债表!K6 | M14: =-假设与情景!$C$46*资产负债表!L6 | N14: =-假设与情景!$C$46*资产负债表!M6 | O14: =-假设与情景!$D$46*资产负债表!D6 | P14: =-假设与情景!$D$46*资产负债表!O6 | Q14: =-假设与情景!$D$46*资产负债表!P6 | R14: =-假设与情景!$D$46*资产负债表!Q6 | S14: =-假设与情景!$D$46*资产负债表!R6
A15: 其他经营项目净额 | B15: 1.09 | C15: 0.68 | D15: 1.26 | E15: =假设与情景!$B$48 | F15: =假设与情景!$B$48 | G15: =假设与情景!$B$48 | H15: =假设与情景!$B$48 | I15: =假设与情景!$B$48 | J15: =假设与情景!$C$48 | K15: =假设与情景!$C$48 | L15: =假设与情景!$C$48 | M15: =假设与情景!$C$48 | N15: =假设与情景!$C$48 | O15: =假设与情景!$D$48 | P15: =假设与情景!$D$48 | Q15: =假设与情景!$D$48 | R15: =假设与情景!$D$48 | S15: =假设与情景!$D$48
A16: 营业利润 | B16: 1037.09 | C16: 1196.89 | D16: 1148.09 | E16: =E8-E9-E10-E11-E12-E13-E14+E15 | F16: =F8-F9-F10-F11-F12-F13-F14+F15 | G16: =G8-G9-G10-G11-G12-G13-G14+G15 | H16: =H8-H9-H10-H11-H12-H13-H14+H15 | I16: =I8-I9-I10-I11-I12-I13-I14+I15 | J16: =J8-J9-J10-J11-J12-J13-J14+J15 | K16: =K8-K9-K10-K11-K12-K13-K14+K15 | L16: =L8-L9-L10-L11-L12-L13-L14+L15 | ... S16: =S8-S9-S10-S11-S12-S13-S14+S15
A17: 营业外收支净额 | B17: -0.46 | C17: -0.5 | D17: -0.54 | E17: =假设与情景!$B$49 | F17: =假设与情景!$B$49 | G17: =假设与情景!$B$49 | H17: =假设与情景!$B$49 | I17: =假设与情景!$B$49 | J17: =假设与情景!$C$49 | K17: =假设与情景!$C$49 | L17: =假设与情景!$C$49 | M17: =假设与情景!$C$49 | N17: =假设与情景!$C$49 | O17: =假设与情景!$D$49 | P17: =假设与情景!$D$49 | Q17: =假设与情景!$D$49 | R17: =假设与情景!$D$49 | S17: =假设与情景!$D$49
A18: 利润总额 | B18: 1036.63 | C18: 1196.39 | D18: 1147.55 | E18: =E16+E17 | F18: =F16+F17 | G18: =G16+G17 | H18: =H16+H17 | I18: =I16+I17 | J18: =J16+J17 | K18: =K16+K17 | L18: =L16+L17 | ... S18: =S16+S17
A19: 所得税费用 | B19: 261.41 | C19: 303.04 | D19: 294.45 | E19: =E18*假设与情景!$B$34 | F19: =F18*假设与情景!$B$34 | G19: =G18*假设与情景!$B$34 | H19: =H18*假设与情景!$B$34 | I19: =I18*假设与情景!$B$34 | J19: =J18*假设与情景!$C$34 | K19: =K18*假设与情景!$C$34 | L19: =L18*假设与情景!$C$34 | M19: =M18*假设与情景!$C$34 | N19: =N18*假设与情景!$C$34 | O19: =O18*假设与情景!$D$34 | P19: =P18*假设与情景!$D$34 | Q19: =Q18*假设与情景!$D$34 | R19: =R18*假设与情景!$D$34 | S19: =S18*假设与情景!$D$34
A20: 净利润 | B20: 775.21 | C20: 893.35 | D20: 853.1 | E20: =E18-E19 | F20: =F18-F19 | G20: =G18-G19 | H20: =H18-H19 | I20: =I18-I19 | J20: =J18-J19 | K20: =K18-K19 | L20: =L18-L19 | ... S20: =S18-S19
A21: 少数股东损益 | B21: 27.87 | C21: 31.07 | D21: 29.9 | E21: =E20*假设与情景!$B$35 | F21: =F20*假设与情景!$B$35 | G21: =G20*假设与情景!$B$35 | H21: =H20*假设与情景!$B$35 | I21: =I20*假设与情景!$B$35 | J21: =J20*假设与情景!$C$35 | K21: =K20*假设与情景!$C$35 | L21: =L20*假设与情景!$C$35 | M21: =M20*假设与情景!$C$35 | N21: =N20*假设与情景!$C$35 | O21: =O20*假设与情景!$D$35 | P21: =P20*假设与情景!$D$35 | Q21: =Q20*假设与情景!$D$35 | R21: =R20*假设与情景!$D$35 | S21: =S20*假设与情景!$D$35
A22: 归属于母公司股东的净利润 | B22: 747.34 | C22: 862.28 | D22: 823.2 | E22: =E20-E21 | F22: =F20-F21 | G22: =G20-G21 | H22: =H20-H21 | I22: =I20-I21 | J22: =J20-J21 | K22: =K20-K21 | L22: =L20-L21 | ... S22: =S20-S21
A23: EPS（元） | B23: =B22/假设与情景!$B$6 | C23: =C22/假设与情景!$B$6 | D23: =D22/假设与情景!$B$6 | E23: =E22/假设与情景!$B$6 | F23: =F22/假设与情景!$B$6 | G23: =G22/假设与情景!$B$6 | H23: =H22/假设与情景!$B$6 | I23: =I22/假设与情景!$B$6 | ... S23: =S22/假设与情景!$B$6
A24: 毛利率 | B24: =1-B9/B6 | C24: =1-C9/C6 | D24: =1-D9/D6 | E24: =1-E9/E6 | F24: =1-F9/F6 | G24: =1-G9/G6 | H24: =1-H9/H6 | I24: =1-I9/I6 | ... S24: =1-S9/S6
A25: 归母净利率 | B25: =B22/B6 | C25: =C22/C6 | D25: =D22/D6 | E25: =E22/E6 | F25: =F22/F6 | G25: =G22/G6 | H25: =H22/H6 | I25: =I22/I6 | ... S25: =S22/S6
A26: 营收增速 | B26: 0.19 | C26: =C6/B6-1 | D26: =D6/C6-1 | E26: =E6/D6-1 | F26: =F6/E6-1 | G26: =G6/F6-1 | H26: =H6/G6-1 | I26: =I6/H6-1 | J26: =J6/D6-1 | K26: =K6/J6-1 | L26: =L6/K6-1 | M26: =M6/L6-1 | N26: =N6/M6-1 | O26: =O6/D6-1 | P26: =P6/O6-1 | Q26: =Q6/P6-1 | R26: =R6/Q6-1 | S26: =S6/R6-1

Sheet 资产负债表
A1: 资产负债表（期末值）
A2: 单位: 人民币亿元 ｜ 现金池=CF期末现金（跨表联动）；固定资产/未分配利润滚动
B3: 历史实际（AkShare/年报） | E3: 悲观情景 | J3: 中性情景 | O3: 乐观情景
B4: 2023A | C4: 2024A | D4: 2025A | E4: 2026E | F4: 2027E | G4: 2028E | H4: 2029E | I4: 2030E | J4: 2026E | K4: 2027E | L4: 2028E | M4: 2029E | N4: 2030E | O4: 2026E | P4: 2027E | Q4: 2028E | R4: 2029E | S4: 2030E
A6: 现金类资产池（货币资金+拆出+买入返售+债权投资等） | B6: 1834.52 | C6: 1964.3 | D6: 1911.47 | E6: =现金流量表!E24 | F6: =现金流量表!F24 | G6: =现金流量表!G24 | H6: =现金流量表!H24 | I6: =现金流量表!I24 | J6: =现金流量表!J24 | K6: =现金流量表!K24 | L6: =现金流量表!L24 | ... S6: =现金流量表!S24
A7: 应收款项融资 | B7: 0 | C7: 0 | D7: 44.57 | E7: =利润表!E6*假设与情景!$B$41 | F7: =利润表!F6*假设与情景!$B$41 | G7: =利润表!G6*假设与情景!$B$41 | H7: =利润表!H6*假设与情景!$B$41 | I7: =利润表!I6*假设与情景!$B$41 | J7: =利润表!J6*假设与情景!$C$41 | K7: =利润表!K6*假设与情景!$C$41 | L7: =利润表!L6*假设与情景!$C$41 | M7: =利润表!M6*假设与情景!$C$41 | N7: =利润表!N6*假设与情景!$C$41 | O7: =利润表!O6*假设与情景!$D$41 | P7: =利润表!P6*假设与情景!$D$41 | Q7: =利润表!Q6*假设与情景!$D$41 | R7: =利润表!R6*假设与情景!$D$41 | S7: =利润表!S6*假设与情景!$D$41
A8: 存货 | B8: 464.35 | C8: 543.43 | D8: 614.27 | E8: =利润表!E6*假设与情景!$B$39 | F8: =利润表!F6*假设与情景!$B$39 | G8: =利润表!G6*假设与情景!$B$39 | H8: =利润表!H6*假设与情景!$B$39 | I8: =利润表!I6*假设与情景!$B$39 | J8: =利润表!J6*假设与情景!$C$39 | K8: =利润表!K6*假设与情景!$C$39 | L8: =利润表!L6*假设与情景!$C$39 | M8: =利润表!M6*假设与情景!$C$39 | N8: =利润表!N6*假设与情景!$C$39 | O8: =利润表!O6*假设与情景!$D$39 | P8: =利润表!P6*假设与情景!$D$39 | Q8: =利润表!Q6*假设与情景!$D$39 | R8: =利润表!R6*假设与情景!$D$39 | S8: =利润表!S6*假设与情景!$D$39
A9: 固定资产原值 | B9: 330.51 | C9: 366.77 | D9: 391.09 | E9: =D9+假设与情景!$B$38 | F9: =E9+假设与情景!$B$38 | G9: =F9+假设与情景!$B$38 | H9: =G9+假设与情景!$B$38 | I9: =H9+假设与情景!$B$38 | J9: =D9+假设与情景!$C$38 | K9: =J9+假设与情景!$C$38 | L9: =K9+假设与情景!$C$38 | M9: =L9+假设与情景!$C$38 | N9: =M9+假设与情景!$C$38 | O9: =D9+假设与情景!$D$38 | P9: =O9+假设与情景!$D$38 | Q9: =P9+假设与情景!$D$38 | R9: =Q9+假设与情景!$D$38 | S9: =R9+假设与情景!$D$38
A10: 本期折旧摊销（D&A） | B10: 20 | C10: 20.63 | D10: 22.15 | E10: =假设与情景!$B$44*D9+假设与情景!$B$45 | F10: =假设与情景!$B$44*E9+假设与情景!$B$45 | G10: =假设与情景!$B$44*F9+假设与情景!$B$45 | H10: =假设与情景!$B$44*G9+假设与情景!$B$45 | I10: =假设与情景!$B$44*H9+假设与情景!$B$45 | J10: =假设与情景!$C$44*D9+假设与情景!$C$45 | K10: =假设与情景!$C$44*J9+假设与情景!$C$45 | L10: =假设与情景!$C$44*K9+假设与情景!$C$45 | M10: =假设与情景!$C$44*L9+假设与情景!$C$45 | N10: =假设与情景!$C$44*M9+假设与情景!$C$45 | O10: =假设与情景!$D$44*D9+假设与情景!$D$45 | P10: =假设与情景!$D$44*O9+假设与情景!$D$45 | Q10: =假设与情景!$D$44*P9+假设与情景!$D$45 | R10: =假设与情景!$D$44*Q9+假设与情景!$D$45 | S10: =假设与情景!$D$44*R9+假设与情景!$D$45
A11: 累计折旧 | B11: 131.41 | C11: 148.04 | D11: 166.19 | E11: =D11+E10 | F11: =E11+F10 | G11: =F11+G10 | H11: =G11+H10 | I11: =H11+I10 | J11: =D11+J10 | K11: =J11+K10 | L11: =K11+L10 | M11: =L11+M10 | N11: =M11+N10 | O11: =D11+O10 | P11: =O11+P10 | Q11: =P11+Q10 | R11: =Q11+R10 | S11: =R11+S10
A12: 固定资产净值 | B12: =B9-B11 | C12: =C9-C11 | D12: =D9-D11 | E12: =E9-E11 | F12: =F9-F11 | G12: =G9-G11 | H12: =H9-H11 | I12: =I9-I11 | ... S12: =S9-S11
A13: 在建工程 | B13: 21.37 | C13: 21.5 | D13: 24.72 | E13: =D13 | F13: =E13 | G13: =F13 | H13: =G13 | I13: =H13 | J13: =D13 | K13: =J13 | L13: =K13 | M13: =L13 | N13: =M13 | O13: =D13 | P13: =O13 | Q13: =P13 | R13: =Q13 | S13: =R13
A14: 无形资产及使用权等 | B14: 91.04 | C14: 93.59 | D14: 90.24 | E14: =D14 | F14: =E14 | G14: =F14 | H14: =G14 | I14: =H14 | J14: =D14 | K14: =J14 | L14: =K14 | M14: =L14 | N14: =M14 | O14: =D14 | P14: =O14 | Q14: =P14 | R14: =Q14 | S14: =R14
A15: 其他资产（财务公司贷款/递延税/其他） | B15: 116.6 | C15: 147.9 | D15: 128.18 | E15: =D15 | F15: =E15 | G15: =F15 | H15: =G15 | I15: =H15 | J15: =D15 | K15: =J15 | L15: =K15 | M15: =L15 | N15: =M15 | O15: =D15 | P15: =O15 | Q15: =P15 | R15: =Q15 | S15: =R15
A16: 资产总计 | B16: =B6+B7+B8+B12+B13+B14+B15 | C16: =C6+C7+C8+C12+C13+C14+C15 | D16: =D6+D7+D8+D12+D13+D14+D15 | E16: =E6+E7+E8+E12+E13+E14+E15 | F16: =F6+F7+F8+F12+F13+F14+F15 | G16: =G6+G7+G8+G12+G13+G14+G15 | H16: =H6+H7+H8+H12+H13+H14+H15 | I16: =I6+I7+I8+I12+I13+I14+I15 | ... S16: =S6+S7+S8+S12+S13+S14+S15
A17: 吸收存款及同业存放（财务公司） | B17: 120.34 | C17: 231.03 | D17: 180.38 | E17: =D17 | F17: =E17 | G17: =F17 | H17: =G17 | I17: =H17 | J17: =D17 | K17: =J17 | L17: =K17 | M17: =L17 | N17: =M17 | O17: =D17 | P17: =O17 | Q17: =P17 | R17: =Q17 | S17: =R17
A18: 合同负债 | B18: 141.26 | C18: 95.92 | D18: 80.07 | E18: =利润表!E6*假设与情景!$B$40 | F18: =利润表!F6*假设与情景!$B$40 | G18: =利润表!G6*假设与情景!$B$40 | H18: =利润表!H6*假设与情景!$B$40 | I18: =利润表!I6*假设与情景!$B$40 | J18: =利润表!J6*假设与情景!$C$40 | K18: =利润表!K6*假设与情景!$C$40 | L18: =利润表!L6*假设与情景!$C$40 | M18: =利润表!M6*假设与情景!$C$40 | N18: =利润表!N6*假设与情景!$C$40 | O18: =利润表!O6*假设与情景!$D$40 | P18: =利润表!P6*假设与情景!$D$40 | Q18: =利润表!Q6*假设与情景!$D$40 | R18: =利润表!R6*假设与情景!$D$40 | S18: =利润表!S6*假设与情景!$D$40
A19: 其他经营性负债 | B19: 228.26 | C19: 241.26 | D19: 237.86 | E19: =利润表!E6*假设与情景!$B$42 | F19: =利润表!F6*假设与情景!$B$42 | G19: =利润表!G6*假设与情景!$B$42 | H19: =利润表!H6*假设与情景!$B$42 | I19: =利润表!I6*假设与情景!$B$42 | J19: =利润表!J6*假设与情景!$C$42 | K19: =利润表!K6*假设与情景!$C$42 | L19: =利润表!L6*假设与情景!$C$42 | M19: =利润表!M6*假设与情景!$C$42 | N19: =利润表!N6*假设与情景!$C$42 | O19: =利润表!O6*假设与情景!$D$42 | P19: =利润表!P6*假设与情景!$D$42 | Q19: =利润表!Q6*假设与情景!$D$42 | R19: =利润表!R6*假设与情景!$D$42 | S19: =利润表!S6*假设与情景!$D$42
A20: 负债合计 | B20: =B17+B18+B19 | C20: =C17+C18+C19 | D20: =D17+D18+D19 | E20: =E17+E18+E19 | F20: =F17+F18+F19 | G20: =G17+G18+G19 | H20: =H17+H18+H19 | I20: =I17+I18+I19 | ... S20: =S17+S18+S19
A21: 股本 | B21: 12.56 | C21: 12.56 | D21: 12.52 | E21: =D21 | F21: =E21 | G21: =F21 | H21: =G21 | I21: =H21 | J21: =D21 | K21: =J21 | L21: =K21 | M21: =L21 | N21: =M21 | O21: =D21 | P21: =O21 | Q21: =P21 | R21: =Q21 | S21: =R21
A22: 盈余公积 | B22: 389.99 | C22: 466.36 | D22: 505.43 | E22: =D22+利润表!E22*假设与情景!$B$43 | F22: =E22+利润表!F22*假设与情景!$B$43 | G22: =F22+利润表!G22*假设与情景!$B$43 | H22: =G22+利润表!H22*假设与情景!$B$43 | I22: =H22+利润表!I22*假设与情景!$B$43 | J22: =D22+利润表!J22*假设与情景!$C$43 | K22: =J22+利润表!K22*假设与情景!$C$43 | L22: =K22+利润表!L22*假设与情景!$C$43 | M22: =L22+利润表!M22*假设与情景!$C$43 | N22: =M22+利润表!N22*假设与情景!$C$43 | O22: =D22+利润表!O22*假设与情景!$D$43 | P22: =O22+利润表!P22*假设与情景!$D$43 | Q22: =P22+利润表!Q22*假设与情景!$D$43 | R22: =Q22+利润表!R22*假设与情景!$D$43 | S22: =R22+利润表!S22*假设与情景!$D$43
A23: 一般风险准备 | B23: 10.62 | C23: 10.62 | D23: 10.62 | E23: =D23 | F23: =E23 | G23: =F23 | H23: =G23 | I23: =H23 | J23: =D23 | K23: =J23 | L23: =K23 | M23: =L23 | N23: =M23 | O23: =D23 | P23: =O23 | Q23: =P23 | R23: =Q23 | S23: =R23
A24: 未分配利润 | B24: 1729.83 | C24: 1827.87 | D24: 1919.05 | E24: =D24+利润表!E22-利润表!E22*假设与情景!$B$36-假设与情景!$B$37-利润表!E22*假设与情景!$B$43 | F24: =E24+利润表!F22-利润表!F22*假设与情景!$B$36-假设与情景!$B$37-利润表!F22*假设与情景!$B$43 | G24: =F24+利润表!G22-利润表!G22*假设与情景!$B$36-假设与情景!$B$37-利润表!G22*假设与情景!$B$43 | H24: =G24+利润表!H22-利润表!H22*假设与情景!$B$36-假设与情景!$B$37-利润表!H22*假设与情景!$B$43 | I24: =H24+利润表!I22-利润表!I22*假设与情景!$B$36-假设与情景!$B$37-利润表!I22*假设与情景!$B$43 | J24: =D24+利润表!J22-利润表!J22*假设与情景!$C$36-假设与情景!$C$37-利润表!J22*假设与情景!$C$43 | K24: =J24+利润表!K22-利润表!K22*假设与情景!$C$36-假设与情景!$C$37-利润表!K22*假设与情景!$C$43 | L24: =K24+利润表!L22-利润表!L22*假设与情景!$C$36-假设与情景!$C$37-利润表!L22*假设与情景!$C$43 | M24: =L24+利润表!M22-利润表!M22*假设与情景!$C$36-假设与情景!$C$37-利润表!M22*假设与情景!$C$43 | N24: =M24+利润表!N22-利润表!N22*假设与情景!$C$36-假设与情景!$C$37-利润表!N22*假设与情景!$C$43 | O24: =D24+利润表!O22-利润表!O22*假设与情景!$D$36-假设与情景!$D$37-利润表!O22*假设与情景!$D$43 | P24: =O24+利润表!P22-利润表!P22*假设与情景!$D$36-假设与情景!$D$37-利润表!P22*假设与情景!$D$43 | Q24: =P24+利润表!Q22-利润表!Q22*假设与情景!$D$36-假设与情景!$D$37-利润表!Q22*假设与情景!$D$43 | R24: =Q24+利润表!R22-利润表!R22*假设与情景!$D$36-假设与情景!$D$37-利润表!R22*假设与情景!$D$43 | S24: =R24+利润表!S22-利润表!S22*假设与情景!$D$36-假设与情景!$D$37-利润表!S22*假设与情景!$D$43
A25: 库存股 | B25: 0 | C25: 0 | D25: -1.2 | E25: =D25 | F25: =E25 | G25: =F25 | H25: =G25 | I25: =H25 | J25: =D25 | K25: =J25 | L25: =K25 | M25: =L25 | N25: =M25 | O25: =D25 | P25: =O25 | Q25: =P25 | R25: =Q25 | S25: =R25
A26: 归属于母公司股东权益合计 | B26: =B21+B22+B23+B24+B25 | C26: =C21+C22+C23+C24+C25 | D26: =D21+D22+D23+D24+D25 | E26: =E21+E22+E23+E24+E25 | F26: =F21+F22+F23+F24+F25 | G26: =G21+G22+G23+G24+G25 | H26: =H21+H22+H23+H24+H25 | I26: =I21+I22+I23+I24+I25 | ... S26: =S21+S22+S23+S24+S25
A27: 少数股东权益 | B27: 79.88 | C27: 89.05 | D27: 93.21 | E27: =D27+利润表!E21*(1-假设与情景!$B$50) | F27: =E27+利润表!F21*(1-假设与情景!$B$50) | G27: =F27+利润表!G21*(1-假设与情景!$B$50) | H27: =G27+利润表!H21*(1-假设与情景!$B$50) | I27: =H27+利润表!I21*(1-假设与情景!$B$50) | J27: =D27+利润表!J21*(1-假设与情景!$C$50) | K27: =J27+利润表!K21*(1-假设与情景!$C$50) | L27: =K27+利润表!L21*(1-假设与情景!$C$50) | M27: =L27+利润表!M21*(1-假设与情景!$C$50) | N27: =M27+利润表!N21*(1-假设与情景!$C$50) | O27: =D27+利润表!O21*(1-假设与情景!$D$50) | P27: =O27+利润表!P21*(1-假设与情景!$D$50) | Q27: =P27+利润表!Q21*(1-假设与情景!$D$50) | R27: =Q27+利润表!R21*(1-假设与情景!$D$50) | S27: =R27+利润表!S21*(1-假设与情景!$D$50)
A28: 所有者权益合计 | B28: =B26+B27 | C28: =C26+C27 | D28: =D26+D27 | E28: =E26+E27 | F28: =F26+F27 | G28: =G26+G27 | H28: =H26+H27 | I28: =I26+I27 | ... S28: =S26+S27
A29: 负债和所有者权益总计 | B29: =B20+B28 | C29: =C20+C28 | D29: =D20+D28 | E29: =E20+E28 | F29: =F20+F28 | G29: =G20+G28 | H29: =H20+H28 | I29: =I20+I28 | ... S29: =S20+S28
A30: 平衡检查（资产-负债权益） | B30: =B16-B29 | C30: =C16-C29 | D30: =D16-D29 | E30: =E16-E29 | F30: =F16-F29 | G30: =G16-G29 | H30: =H16-H29 | I30: =I16-I29 | ... S30: =S16-S29
A31: 报表口径资产总计（核对用） | B31: 2727 | C31: 2989.45 | D31: 3038.35

Sheet 现金流量表
A1: 现金流量表（间接法简化）
A2: 单位: 人民币亿元 ｜ 现金池口径=广义金融资产；历史含倒挤调节项，预测为0
B3: 历史实际（AkShare/年报） | E3: 悲观情景 | J3: 中性情景 | O3: 乐观情景
B4: 2023A | C4: 2024A | D4: 2025A | E4: 2026E | F4: 2027E | G4: 2028E | H4: 2029E | I4: 2030E | J4: 2026E | K4: 2027E | L4: 2028E | M4: 2029E | N4: 2030E | O4: 2026E | P4: 2027E | Q4: 2028E | R4: 2029E | S4: 2030E
A6: 净利润 | B6: 775.21 | C6: 893.35 | D6: 853.1 | E6: =利润表!E20 | F6: =利润表!F20 | G6: =利润表!G20 | H6: =利润表!H20 | I6: =利润表!I20 | J6: =利润表!J20 | K6: =利润表!K20 | L6: =利润表!L20 | ... S6: =利润表!S20
A7: 折旧摊销 | B7: =资产负债表!B10 | C7: =资产负债表!C10 | D7: =资产负债表!D10 | E7: =资产负债表!E10 | F7: =资产负债表!F10 | G7: =资产负债表!G10 | H7: =资产负债表!H10 | I7: =资产负债表!I10 | ... S7: =资产负债表!S10
A8: 存货的减少（增加为负） | B8: -76.11 | C8: -79.08 | D8: -70.84 | E8: =资产负债表!D8-资产负债表!E8 | F8: =资产负债表!E8-资产负债表!F8 | G8: =资产负债表!F8-资产负债表!G8 | H8: =资产负债表!G8-资产负债表!H8 | I8: =资产负债表!H8-资产负债表!I8 | J8: =资产负债表!D8-资产负债表!J8 | K8: =资产负债表!J8-资产负债表!K8 | L8: =资产负债表!K8-资产负债表!L8 | M8: =资产负债表!L8-资产负债表!M8 | N8: =资产负债表!M8-资产负债表!N8 | O8: =资产负债表!D8-资产负债表!O8 | P8: =资产负债表!O8-资产负债表!P8 | Q8: =资产负债表!P8-资产负债表!Q8 | R8: =资产负债表!Q8-资产负债表!R8 | S8: =资产负债表!R8-资产负债表!S8
A9: 经营性应收的减少（增加为负） | B9: 0 | C9: 0 | D9: -44.57 | E9: =资产负债表!D7-资产负债表!E7 | F9: =资产负债表!E7-资产负债表!F7 | G9: =资产负债表!F7-资产负债表!G7 | H9: =资产负债表!G7-资产负债表!H7 | I9: =资产负债表!H7-资产负债表!I7 | J9: =资产负债表!D7-资产负债表!J7 | K9: =资产负债表!J7-资产负债表!K7 | L9: =资产负债表!K7-资产负债表!L7 | M9: =资产负债表!L7-资产负债表!M7 | N9: =资产负债表!M7-资产负债表!N7 | O9: =资产负债表!D7-资产负债表!O7 | P9: =资产负债表!O7-资产负债表!P7 | Q9: =资产负债表!P7-资产负债表!Q7 | R9: =资产负债表!Q7-资产负债表!R7 | S9: =资产负债表!R7-资产负债表!S7
A10: 经营性应付的增加 | B10: 3.72 | C10: -32.33 | D10: -19.25 | E10: =资产负债表!E18+资产负债表!E19-资产负债表!D18-资产负债表!D19 | F10: =资产负债表!F18+资产负债表!F19-资产负债表!E18-资产负债表!E19 | G10: =资产负债表!G18+资产负债表!G19-资产负债表!F18-资产负债表!F19 | H10: =资产负债表!H18+资产负债表!H19-资产负债表!G18-资产负债表!G19 | I10: =资产负债表!I18+资产负债表!I19-资产负债表!H18-资产负债表!H19 | J10: =资产负债表!J18+资产负债表!J19-资产负债表!D18-资产负债表!D19 | K10: =资产负债表!K18+资产负债表!K19-资产负债表!J18-资产负债表!J19 | L10: =资产负债表!L18+资产负债表!L19-资产负债表!K18-资产负债表!K19 | M10: =资产负债表!M18+资产负债表!M19-资产负债表!L18-资产负债表!L19 | N10: =资产负债表!N18+资产负债表!N19-资产负债表!M18-资产负债表!M19 | O10: =资产负债表!O18+资产负债表!O19-资产负债表!D18-资产负债表!D19 | P10: =资产负债表!P18+资产负债表!P19-资产负债表!O18-资产负债表!O19 | Q10: =资产负债表!Q18+资产负债表!Q19-资产负债表!P18-资产负债表!P19 | R10: =资产负债表!R18+资产负债表!R19-资产负债表!Q18-资产负债表!Q19 | S10: =资产负债表!S18+资产负债表!S19-资产负债表!R18-资产负债表!R19
A11: 其他调整（历史倒挤） | B11: =B12-SUM(B6:B10) | C11: =C12-SUM(C6:C10) | D11: =D12-SUM(D6:D10) | E11: 0 | F11: 0 | G11: 0 | H11: 0 | I11: 0 | J11: 0 | K11: 0 | L11: 0 | M11: 0 | N11: 0 | O11: 0 | P11: 0 | Q11: 0 | R11: 0 | S11: 0
A12: 经营活动现金流量净额 | B12: 665.93 | C12: 924.64 | D12: 615.22 | E12: =SUM(E6:E11) | F12: =SUM(F6:F11) | G12: =SUM(G6:G11) | H12: =SUM(H6:H11) | I12: =SUM(I6:I11) | J12: =SUM(J6:J11) | K12: =SUM(K6:K11) | L12: =SUM(L6:L11) | ... S12: =SUM(S6:S11)
A13: 购建固定资产等（CapEx） | B13: -26.2 | C13: -46.79 | D13: -31.28 | E13: =-假设与情景!$B$38 | F13: =-假设与情景!$B$38 | G13: =-假设与情景!$B$38 | H13: =-假设与情景!$B$38 | I13: =-假设与情景!$B$38 | J13: =-假设与情景!$C$38 | K13: =-假设与情景!$C$38 | L13: =-假设与情景!$C$38 | M13: =-假设与情景!$C$38 | N13: =-假设与情景!$C$38 | O13: =-假设与情景!$D$38 | P13: =-假设与情景!$D$38 | Q13: =-假设与情景!$D$38 | R13: =-假设与情景!$D$38 | S13: =-假设与情景!$D$38
A14: 投资活动其他净额（财务公司投资滚动） | B14: -71.05 | C14: 28.94 | D14: -285.14 | E14: 0 | F14: 0 | G14: 0 | H14: 0 | I14: 0 | J14: 0 | K14: 0 | L14: 0 | M14: 0 | N14: 0 | O14: 0 | P14: 0 | Q14: 0 | R14: 0 | S14: 0
A15: 投资活动现金流量净额 | B15: =B13+B14 | C15: =C13+C14 | D15: =D13+D14 | E15: =E13+E14 | F15: =F13+F14 | G15: =G13+G14 | H15: =H13+H14 | I15: =I13+I14 | ... S15: =S13+S14
A16: 归母分红支付 | B16: -587.55 | C16: -709.51 | D16: -672.42 | E16: =-利润表!E22*假设与情景!$B$36 | F16: =-利润表!F22*假设与情景!$B$36 | G16: =-利润表!G22*假设与情景!$B$36 | H16: =-利润表!H22*假设与情景!$B$36 | I16: =-利润表!I22*假设与情景!$B$36 | J16: =-利润表!J22*假设与情景!$C$36 | K16: =-利润表!K22*假设与情景!$C$36 | L16: =-利润表!L22*假设与情景!$C$36 | M16: =-利润表!M22*假设与情景!$C$36 | N16: =-利润表!N22*假设与情景!$C$36 | O16: =-利润表!O22*假设与情景!$D$36 | P16: =-利润表!P22*假设与情景!$D$36 | Q16: =-利润表!Q22*假设与情景!$D$36 | R16: =-利润表!R22*假设与情景!$D$36 | S16: =-利润表!S22*假设与情景!$D$36
A17: 少数股东分红 | B17: -22.05 | C17: -21.64 | D17: -25.7 | E17: =-利润表!E21*假设与情景!$B$50 | F17: =-利润表!F21*假设与情景!$B$50 | G17: =-利润表!G21*假设与情景!$B$50 | H17: =-利润表!H21*假设与情景!$B$50 | I17: =-利润表!I21*假设与情景!$B$50 | J17: =-利润表!J21*假设与情景!$C$50 | K17: =-利润表!K21*假设与情景!$C$50 | L17: =-利润表!L21*假设与情景!$C$50 | M17: =-利润表!M21*假设与情景!$C$50 | N17: =-利润表!N21*假设与情景!$C$50 | O17: =-利润表!O21*假设与情景!$D$50 | P17: =-利润表!P21*假设与情景!$D$50 | Q17: =-利润表!Q21*假设与情景!$D$50 | R17: =-利润表!R21*假设与情景!$D$50 | S17: =-利润表!S21*假设与情景!$D$50
A18: 回购及其他筹资支付 | B18: -1.34 | C18: -1.16 | D18: -61.85 | E18: =-假设与情景!$B$37 | F18: =-假设与情景!$B$37 | G18: =-假设与情景!$B$37 | H18: =-假设与情景!$B$37 | I18: =-假设与情景!$B$37 | J18: =-假设与情景!$C$37 | K18: =-假设与情景!$C$37 | L18: =-假设与情景!$C$37 | M18: =-假设与情景!$C$37 | N18: =-假设与情景!$C$37 | O18: =-假设与情景!$D$37 | P18: =-假设与情景!$D$37 | Q18: =-假设与情景!$D$37 | R18: =-假设与情景!$D$37 | S18: =-假设与情景!$D$37
A19: 筹资活动现金流量净额 | B19: =B16+B17+B18 | C19: =C16+C17+C18 | D19: =D16+D17+D18 | E19: =E16+E17+E18 | F19: =F16+F17+F18 | G19: =G16+G17+G18 | H19: =H16+H17+H18 | I19: =I16+I17+I18 | ... S19: =S16+S17+S18
A20: 三项活动合计 | B20: =B12+B15+B19 | C20: =C12+C15+C19 | D20: =D12+D15+D19 | E20: =E12+E15+E19 | F20: =F12+F15+F19 | G20: =G12+G15+G19 | H20: =H12+H15+H19 | I20: =I12+I15+I19 | ... S20: =S12+S15+S19
A21: 调节项（现金池口径差异） | B21: 85.21 | C21: -66.33 | D21: 382.64 | E21: 0 | F21: 0 | G21: 0 | H21: 0 | I21: 0 | J21: 0 | K21: 0 | L21: 0 | M21: 0 | N21: 0 | O21: 0 | P21: 0 | Q21: 0 | R21: 0 | S21: 0
A22: 现金净变动 | B22: =B20+B21 | C22: =C20+C21 | D22: =D20+D21 | E22: =E20+E21 | F22: =F20+F21 | G22: =G20+G21 | H22: =H20+H21 | I22: =I20+I21 | ... S22: =S20+S21
A23: 期初现金池 | B23: 1769.51 | C23: 1834.52 | D23: 1964.3 | E23: =资产负债表!D6 | F23: =资产负债表!E6 | G23: =资产负债表!F6 | H23: =资产负债表!G6 | I23: =资产负债表!H6 | J23: =资产负债表!D6 | K23: =资产负债表!J6 | L23: =资产负债表!K6 | M23: =资产负债表!L6 | N23: =资产负债表!M6 | O23: =资产负债表!D6 | P23: =资产负债表!O6 | Q23: =资产负债表!P6 | R23: =资产负债表!Q6 | S23: =资产负债表!R6
A24: 期末现金池 | B24: =B23+B22 | C24: =C23+C22 | D24: =D23+D22 | E24: =E23+E22 | F24: =F23+F22 | G24: =G23+G22 | H24: =H23+H22 | I24: =I23+I22 | ... S24: =S23+S22
A25: 简化自由现金流（OCF-CapEx） | B25: =B12+B13 | C25: =C12+C13 | D25: =D12+D13 | E25: =E12+E13 | F25: =F12+F13 | G25: =G12+G13 | H25: =H12+H13 | I25: =I12+I13 | ... S25: =S12+S13
A26: 分红+回购覆盖倍数 | B26: =IF((B16+B18)<0,B25/-(B16+B18),0) | C26: =IF((C16+C18)<0,C25/-(C16+C18),0) | D26: =IF((D16+D18)<0,D25/-(D16+D18),0) | E26: =IF((E16+E18)<0,E25/-(E16+E18),0) | F26: =IF((F16+F18)<0,F25/-(F16+F18),0) | G26: =IF((G16+G18)<0,G25/-(G16+G18),0) | H26: =IF((H16+H18)<0,H25/-(H16+H18),0) | I26: =IF((I16+I18)<0,I25/-(I16+I18),0) | ... S26: =IF((S16+S18)<0,S25/-(S16+S18),0)
A27: 报表口径期末现金及等价物（核对） | B27: 1503.6 | C27: 1699.7 | D27: 1264.26

Sheet 情景对比
A1: 三情景关键结果对比（取自三张主表对应情景块）
A2: 悲观/中性/乐观分别对应利润表-资产负债表-现金流量表的 E-I / J-N / O-S 列
A4: 指标 | B4: 悲观26E | C4: 悲观30E | D4: 悲观CAGR | E4: 中性26E | F4: 中性30E | G4: 中性CAGR | H4: 乐观26E | I4: 乐观30E | J4: 乐观CAGR
A5: 营业收入（亿） | B5: =利润表!E6 | C5: =利润表!I6 | D5: =(利润表!I6/利润表!$D$6)^(1/5)-1 | E5: =利润表!J6 | F5: =利润表!N6 | G5: =(利润表!N6/利润表!$D$6)^(1/5)-1 | H5: =利润表!O6 | I5: =利润表!S6 | J5: =(利润表!S6/利润表!$D$6)^(1/5)-1
A6: 归母净利润（亿） | B6: =利润表!E22 | C6: =利润表!I22 | D6: =(利润表!I22/利润表!$D$22)^(1/5)-1 | E6: =利润表!J22 | F6: =利润表!N22 | G6: =(利润表!N22/利润表!$D$22)^(1/5)-1 | H6: =利润表!O22 | I6: =利润表!S22 | J6: =(利润表!S22/利润表!$D$22)^(1/5)-1
A7: EPS（元） | B7: =利润表!E23 | C7: =利润表!I23 | D7: — | E7: =利润表!J23 | F7: =利润表!N23 | G7: — | H7: =利润表!O23 | I7: =利润表!S23 | J7: —
A8: DPS（元） | B8: =利润表!E22*假设与情景!$B$36/假设与情景!$B$6 | C8: =利润表!I22*假设与情景!$B$36/假设与情景!$B$6 | D8: — | E8: =利润表!J22*假设与情景!$C$36/假设与情景!$B$6 | F8: =利润表!N22*假设与情景!$C$36/假设与情景!$B$6 | G8: — | H8: =利润表!O22*假设与情景!$D$36/假设与情景!$B$6 | I8: =利润表!S22*假设与情景!$D$36/假设与情景!$B$6 | J8: —
A9: 经营活动净现金流（亿） | B9: =现金流量表!E12 | C9: =现金流量表!I12 | D9: — | E9: =现金流量表!J12 | F9: =现金流量表!N12 | G9: — | H9: =现金流量表!O12 | I9: =现金流量表!S12 | J9: —
A10: 简化FCF（亿） | B10: =现金流量表!E25 | C10: =现金流量表!I25 | D10: — | E10: =现金流量表!J25 | F10: =现金流量表!N25 | G10: — | H10: =现金流量表!O25 | I10: =现金流量表!S25 | J10: —
A11: 期末现金池（亿） | B11: =资产负债表!E6 | C11: =资产负债表!I6 | D11: — | E11: =资产负债表!J6 | F11: =资产负债表!N6 | G11: — | H11: =资产负债表!O6 | I11: =资产负债表!S6 | J11: —
A12: 归母权益（亿） | B12: =资产负债表!E26 | C12: =资产负债表!I26 | D12: — | E12: =资产负债表!J26 | F12: =资产负债表!N26 | G12: — | H12: =资产负债表!O26 | I12: =资产负债表!S26 | J12: —
A13: 每股净资产（元） | B13: =资产负债表!E26/假设与情景!$B$6 | C13: =资产负债表!I26/假设与情景!$B$6 | D13: — | E13: =资产负债表!J26/假设与情景!$B$6 | F13: =资产负债表!N26/假设与情景!$B$6 | G13: — | H13: =资产负债表!O26/假设与情景!$B$6 | I13: =资产负债表!S26/假设与情景!$B$6 | J13: —
A14: ROE（归母） | B14: =利润表!E22/资产负债表!E26 | C14: =利润表!I22/资产负债表!I26 | D14: — | E14: =利润表!J22/资产负债表!J26 | F14: =利润表!N22/资产负债表!N26 | G14: — | H14: =利润表!O22/资产负债表!O26 | I14: =利润表!S22/资产负债表!S26 | J14: —
A15: 隐含PE（现价） | B15: =假设与情景!$B$5/利润表!E23 | C15: =假设与情景!$B$5/利润表!I23 | D15: — | E15: =假设与情景!$B$5/利润表!J23 | F15: =假设与情景!$B$5/利润表!N23 | G15: — | H15: =假设与情景!$B$5/利润表!O23 | I15: =假设与情景!$B$5/利润表!S23 | J15: —
A16: 隐含PB（现价） | B16: =假设与情景!$B$5/(资产负债表!E26/假设与情景!$B$6) | C16: =假设与情景!$B$5/(资产负债表!I26/假设与情景!$B$6) | D16: — | E16: =假设与情景!$B$5/(资产负债表!J26/假设与情景!$B$6) | F16: =假设与情景!$B$5/(资产负债表!N26/假设与情景!$B$6) | G16: — | H16: =假设与情景!$B$5/(资产负债表!O26/假设与情景!$B$6) | I16: =假设与情景!$B$5/(资产负债表!S26/假设与情景!$B$6) | J16: —
A18: 注: 26-30E累计简化FCF（亿） | B18: =SUM(现金流量表!E25:I25) | C18: — | D18: — | E18: =SUM(现金流量表!J25:N25) | F18: — | G18: — | H18: =SUM(现金流量表!O25:S25) | I18: — | J18: —

Sheet 检查
A1: 模型平衡与勾稽检查
A2: 全部应为 ✓ 或 0（历史现金勾稽与RE滚动除外，见注）
B4: 2023A | C4: 2024A | D4: 2025A | E4: 2026E | F4: 2027E | G4: 2028E | H4: 2029E | I4: 2030E | J4: 2026E | K4: 2027E | L4: 2028E | M4: 2029E | N4: 2030E | O4: 2026E | P4: 2027E | Q4: 2028E | R4: 2029E | S4: 2030E
A5: 资产负债表平衡（|差|<0.5） | B5: =IF(ABS(资产负债表!B30)<0.5,"✓","✗") | C5: =IF(ABS(资产负债表!C30)<0.5,"✓","✗") | D5: =IF(ABS(资产负债表!D30)<0.5,"✓","✗") | E5: =IF(ABS(资产负债表!E30)<0.5,"✓","✗") | F5: =IF(ABS(资产负债表!F30)<0.5,"✓","✗") | G5: =IF(ABS(资产负债表!G30)<0.5,"✓","✗") | H5: =IF(ABS(资产负债表!H30)<0.5,"✓","✗") | I5: =IF(ABS(资产负债表!I30)<0.5,"✓","✗") | ... S5: =IF(ABS(资产负债表!S30)<0.5,"✓","✗")
A6: 资产分项加总-报表值（历史） | B6: =资产负债表!B16-资产负债表!B31 | C6: =资产负债表!C16-资产负债表!C31 | D6: =资产负债表!D16-资产负债表!D31 | E6: =资产负债表!E16-资产负债表!E31 | F6: =资产负债表!F16-资产负债表!F31 | G6: =资产负债表!G16-资产负债表!G31 | H6: =资产负债表!H16-资产负债表!H31 | I6: =资产负债表!I16-资产负债表!I31 | ... S6: =资产负债表!S16-资产负债表!S31
A7: CF净利润=IS净利润 | B7: =现金流量表!B6-利润表!B20 | C7: =现金流量表!C6-利润表!C20 | D7: =现金流量表!D6-利润表!D20 | E7: =现金流量表!E6-利润表!E20 | F7: =现金流量表!F6-利润表!F20 | G7: =现金流量表!G6-利润表!G20 | H7: =现金流量表!H6-利润表!H20 | I7: =现金流量表!I6-利润表!I20 | ... S7: =现金流量表!S6-利润表!S20
A8: 期末现金池=BS现金类 | B8: =现金流量表!B24-资产负债表!B6 | C8: =现金流量表!C24-资产负债表!C6 | D8: =现金流量表!D24-资产负债表!D6 | E8: =现金流量表!E24-资产负债表!E6 | F8: =现金流量表!F24-资产负债表!F6 | G8: =现金流量表!G24-资产负债表!G6 | H8: =现金流量表!H24-资产负债表!H6 | I8: =现金流量表!I24-资产负债表!I6 | ... S8: =现金流量表!S24-资产负债表!S6
A9: BS现金类-报表期末现金（口径差） | B9: =资产负债表!B6-现金流量表!B27 | C9: =资产负债表!C6-现金流量表!C27 | D9: =资产负债表!D6-现金流量表!D27 | E9: =资产负债表!E6-现金流量表!E27 | F9: =资产负债表!F6-现金流量表!F27 | G9: =资产负债表!G6-现金流量表!G27 | H9: =资产负债表!H6-现金流量表!H27 | I9: =资产负债表!I6-现金流量表!I27 | ... S9: =资产负债表!S6-现金流量表!S27
A10: 存货增速-营收增速（pct） | B10: — | C10: =(资产负债表!C8/资产负债表!B8-1)-(利润表!C6/利润表!B6-1) | D10: =(资产负债表!D8/资产负债表!C8-1)-(利润表!D6/利润表!C6-1) | E10: =(资产负债表!E8/资产负债表!D8-1)-(利润表!E6/利润表!D6-1) | F10: =(资产负债表!F8/资产负债表!E8-1)-(利润表!F6/利润表!E6-1) | G10: =(资产负债表!G8/资产负债表!F8-1)-(利润表!G6/利润表!F6-1) | H10: =(资产负债表!H8/资产负债表!G8-1)-(利润表!H6/利润表!G6-1) | I10: =(资产负债表!I8/资产负债表!H8-1)-(利润表!I6/利润表!H6-1) | J10: =(资产负债表!J8/资产负债表!I8-1)-(利润表!J6/利润表!I6-1) | ... S10: =(资产负债表!S8/资产负债表!R8-1)-(利润表!S6/利润表!R6-1)
A11: 有效税率 | B11: =利润表!B19/利润表!B18 | C11: =利润表!C19/利润表!C18 | D11: =利润表!D19/利润表!D18 | E11: =利润表!E19/利润表!E18 | F11: =利润表!F19/利润表!F18 | G11: =利润表!G19/利润表!G18 | H11: =利润表!H19/利润表!H18 | I11: =利润表!I19/利润表!I18 | ... S11: =利润表!S19/利润表!S18
A12: 分红回购覆盖倍数 | B12: =现金流量表!B26 | C12: =现金流量表!C26 | D12: =现金流量表!D26 | E12: =现金流量表!E26 | F12: =现金流量表!F26 | G12: =现金流量表!G26 | H12: =现金流量表!H26 | I12: =现金流量表!I26 | ... S12: =现金流量表!S26
A14: 注1: 行9 现金类-报表期末现金 为已知口径差异（含存放央行款项、受限资金等），历史约200-400亿属正常。
A15: 注2: 2025A 未分配利润滚动核对: 期初1827.87+归母823.20-分红672.42-其他筹资61.85-盈余提取39.07-期末1919.05=残差约20.5亿（回购注销的权益会计处理），属报表实际口径。
A16: 注3: 历史CF第11行"其他调整"为倒挤项（报表间接法分项未完整披露），预测年为0。

Sheet 数据底稿
A1: 数据底稿（AkShare 新浪财经, sh600519, 采集2026-08-31）
A3: 科目（亿元） | B3: 2021A | C3: 2022A | D3: 2023A | E3: 2024A | F3: 2025A | G3: 2026H1
A4: 营业收入 | B4: 1061.9 | C4: 1241 | D4: 1476.94 | E4: 1708.99 | F4: 1688.38 | G4: 907.03
A5: 归母净利润 | B5: 524.6 | C5: 627.17 | D5: 747.34 | E5: 862.28 | F5: 823.2 | G5: 445.17
A6: 营业总收入 | B6: 1094.64 | C6: 1275.54 | D6: 1505.6 | E6: 1741.44 | F6: 1720.54 | G6: 922.78
A7: 税金及附加 | B7: 153.04 | C7: 184.96 | D7: 222.34 | E7: 269.26 | F7: 273.54 | G7: 146.82
A8: 销售费用 | B8: 27.37 | C8: 32.98 | D8: 46.49 | E8: 56.39 | F8: 72.53 | G8: 32.06
A9: 经营活动净现金流 | B9: 640.29 | C9: 366.99 | D9: 665.93 | E9: 924.64 | F9: 615.22 | G9: 706.91
A10: CapEx | B10: 34.09 | C10: 53.07 | D10: 26.2 | E10: 46.79 | F10: 31.28 | G10: 8.32
A11: 分红支付（年内） | B11: 264.76 | C11: 573.7 | D11: 587.55 | E11: 709.51 | F11: 672.42 | G11: 350.44
A12: 资产总计 | B12: 2551.68 | C12: 2545.01 | D12: 2727 | E12: 2989.45 | F12: 3038.35 | G12: 3090.51
A13: 存货 | B13: 333.94 | C13: 388.24 | D13: 464.35 | E13: 543.43 | F13: 614.27 | G13: 613.17
A14: 合同负债 | B14: 127.18 | C14: 154.72 | D14: 141.26 | E14: 95.92 | F14: 80.07 | G14: 31.78
A15: 归母权益 | B15: 1895.39 | C15: 1974.8 | D15: 2156.69 | E15: 2331.06 | F15: 2446.38 | G15: 2512.54
A16: 现金类资产池 | B16: 1870.48 | C16: 1769.51 | D16: 1834.52 | E16: 1964.3 | F16: 1911.47 | G16: 2003.29
A20: 2026H1实际: 营收907.03(+1.48%)、归母净利445.17(-1.95%)、OCF 706.91(财务公司存款波动)。模型2026E营收增速: 悲观-2%/中性+2%/乐观+4%。
A21: 来源: AkShare新浪财经财报接口（元→亿元换算）、2025年报（2026-04披露）、2026中报（2026-08-15披露）、腾讯行情（2026-08-31收盘1299.52元）。
A22: 口径说明: 现金类资产池=货币资金+拆出资金+买入返售+一年内到期非流动资产+债权投资+其他债权投资（含财务公司金融资产，宽于报表"现金及现金等价物"）。
